import React from 'react';
import { render, screen } from '@testing-library/react';
import userEvent from '@testing-library/user-event';
import ErrorBoundary from '../ErrorBoundary';

// Mock console.error to prevent test noise
const originalError = console.error;
beforeAll(() => {
  console.error = jest.fn();
});

afterAll(() => {
  console.error = originalError;
});

const ThrowError = ({ shouldThrow }: { shouldThrow: boolean }) => {
  if (shouldThrow) {
    throw new Error('Test error');
  }
  return <div>No error</div>;
};

describe('ErrorBoundary', () => {
  it('renders children when there is no error', () => {
    render(
      <ErrorBoundary>
        <div>Test content</div>
      </ErrorBoundary>
    );

    expect(screen.getByText('Test content')).toBeInTheDocument();
  });

  it('renders error UI when there is an error', () => {
    render(
      <ErrorBoundary>
        <ThrowError shouldThrow={true} />
      </ErrorBoundary>
    );

    expect(screen.getByText('Something went wrong')).toBeInTheDocument();
    expect(screen.getByText('Test error')).toBeInTheDocument();
    expect(screen.getByRole('button', { name: 'Try Again' })).toBeInTheDocument();
  });

  it('allows retry functionality', async () => {
    const user = userEvent.setup();

    const TestComponent = () => {
      const [shouldThrow, setShouldThrow] = React.useState(true);

      React.useEffect(() => {
        const timer = setTimeout(() => setShouldThrow(false), 100);
        return () => clearTimeout(timer);
      }, []);

      return <ThrowError shouldThrow={shouldThrow} />;
    };

    render(
      <ErrorBoundary>
        <TestComponent />
      </ErrorBoundary>
    );

    expect(screen.getByText('Something went wrong')).toBeInTheDocument();

    const retryButton = screen.getByRole('button', { name: 'Try Again' });
    await user.click(retryButton);

    // After retry, component should attempt to render again
    expect(screen.getByText('Something went wrong')).toBeInTheDocument();
  });

  it('calls onError callback when error occurs', () => {
    const onError = jest.fn();

    render(
      <ErrorBoundary onError={onError}>
        <ThrowError shouldThrow={true} />
      </ErrorBoundary>
    );

    expect(onError).toHaveBeenCalledWith(
      expect.any(Error),
      expect.objectContaining({
        componentStack: expect.any(String),
      })
    );
  });

  it('renders custom fallback component', () => {
    const CustomFallback = ({ error, retry }: { error: Error; retry: () => void }) => (
      <div>
        <h1>Custom Error</h1>
        <p>{error.message}</p>
        <button onClick={retry}>Custom Retry</button>
      </div>
    );

    render(
      <ErrorBoundary fallback={CustomFallback}>
        <ThrowError shouldThrow={true} />
      </ErrorBoundary>
    );

    expect(screen.getByText('Custom Error')).toBeInTheDocument();
    expect(screen.getByText('Test error')).toBeInTheDocument();
    expect(screen.getByRole('button', { name: 'Custom Retry' })).toBeInTheDocument();
  });
});
